<?xml version="1.0" ?>
<robot name="wheeltec_robot" xmlns:xacro="http://www.ros.org/wiki/xacro">

    <!-- 左右两个轮子间距是0.265*2=0.53 -->
    <!-- 前后两个轮子距离是0.595 -->
    <!-- <xacro:include filename="$(find turn_on_wheeltec_robot)/urdf/xacro/control.xacro"/> -->


    <!-- 定义参数 -->
    <xacro:property name="wheel_radius" value="0.10"/>
    <xacro:property name="wheel_length" value="0.04"/>
    <xacro:property name="base_size_x" value="0.68"/>
    <xacro:property name="base_size_y" value="0.46"/>
    <xacro:property name="base_size_z" value="0.10"/>
    <xacro:property name="base_mass" value="40.0"/>
    <xacro:property name="wheel_mass" value="5.0"/>

    <!-- 定义底盘 -->
    <link name="base_link">
        <!-- 外观 -->
        <visual>
            <origin xyz="0.30 0 0.10" rpy="0 0 0" />
            <geometry>
                <box size="${base_size_x} ${base_size_y} ${base_size_z}"/>
            </geometry>
            <material name="white">
                <color rgba="1 1 1 1"/>
            </material>
        </visual>
        <!-- 碰撞属性 -->
        <collision>
            <origin xyz="0.30 0 0.10" rpy="0 0 0" />
            <geometry>
                <box size="${base_size_x} ${base_size_y} ${base_size_z}"/>
            </geometry>
        </collision>
        <!-- 惯性属性 -->
        <inertial>
            <mass value="${base_mass}"/>
            <origin xyz="0 0 0" rpy="0 0 0"/>
            <inertia ixx="${base_mass*(base_size_z*base_size_z + base_size_x*base_size_x)/12}" ixy = "0" ixz = "0"
                     iyy="${base_mass*(base_size_y*base_size_y + base_size_x*base_size_x)/12}" iyz= "0"
                     izz="${base_mass*(base_size_y*base_size_y + base_size_z*base_size_z)/12}" />
        </inertial>
    </link>
    <gazebo reference="base_link">
        <material>Gazebo/White</material>
    </gazebo>


    <!-- 左轮 -->
    <joint name="left_wheel_joint" type="continuous">
        <origin xyz="0 0.265 0.10" rpy="0 0 0"/>
        <parent link="base_link"/>
        <child link="left_wheel_link"/>
        <axis xyz="0 1 0"/>
    </joint>


    <link name="left_wheel_link">
        <visual>
            <origin xyz="0 0 0" rpy="-1.5707963 0 0" />
            <geometry>
                <cylinder radius="${wheel_radius}" length="${wheel_length}"/>
            </geometry>
            <material name="black">
                <color rgba="0 0 0 1"/>
            </material>
        </visual>
        <collision>
            <origin xyz="0 0 0" rpy="-1.5707963 0 0" />
            <geometry>
                <cylinder radius="${wheel_radius}" length="${wheel_length}"/>
            </geometry>
        </collision>
        <inertial>
            <mass value="${wheel_mass}"/>
            <origin xyz="0 0 0"/>
            <!-- <inertia ixx="0.01" ixy="0.0" ixz="0.0" iyy="0.01" iyz="0.0" izz="0.01"/> -->
            <inertia ixx="${wheel_mass*(3*wheel_radius*wheel_radius+wheel_length*wheel_length)/12}" ixy = "0" ixz = "0"
                iyy="${wheel_mass*(3*wheel_radius*wheel_radius+wheel_length*wheel_length)/12}" iyz = "0"
                izz="${wheel_mass*wheel_radius*wheel_radius/2}" />
        </inertial>
    </link>
    <gazebo reference="left_wheel_link">
        <material>Gazebo/Black</material>
    </gazebo>

    <!-- 右轮 -->
    <joint name="right_wheel_joint" type="continuous">
        <origin xyz="0 -0.265 0.10" rpy="1.57 0 0"/>
        <parent link="base_link"/>
        <child link="right_wheel_link"/>
        <axis xyz="0 0 1"/>
    </joint>

    <link name="right_wheel_link">
        <visual>
            <origin xyz="0 0 0" rpy="0 0 0" />
            <geometry>
                <cylinder radius="${wheel_radius}" length="${wheel_length}"/>
            </geometry>
            <material name="black">
                <color rgba="0 0 0 1"/>
            </material>
        </visual>
        <collision>
            <origin xyz="0 0 0" rpy="0 0 0" />
            <geometry>
                <cylinder radius="${wheel_radius}" length="${wheel_length}"/>
            </geometry>
        </collision>
        <inertial>
            <mass value="${wheel_mass}"/>
            <origin xyz="0 0 0" rpy="0 0 0"/>
            <inertia ixx="${wheel_mass*(3*wheel_radius*wheel_radius+wheel_length*wheel_length)/12}" ixy = "0" ixz = "0"
                iyy="${wheel_mass*(3*wheel_radius*wheel_radius+wheel_length*wheel_length)/12}" iyz = "0"
                izz="${wheel_mass*wheel_radius*wheel_radius/2}" />
        </inertial>
    </link>
    <gazebo reference="right_wheel_link">
        <material>Gazebo/Black</material>
    </gazebo>

    <!-- 左前轮 -->
    <joint name="left_front_joint" type="continuous">
        <origin xyz="0.595 0.265 0.10" rpy="1.57 0 0"/>
        <parent link="base_link"/>
        <child link="left_front_link"/>
        <axis xyz="0 1 0"/>
    </joint>

    <link name="left_front_link">
        <visual>
            <origin xyz="0 0 0" rpy="0 0 0" />
            <geometry>
                <cylinder radius="${wheel_radius}" length="${wheel_length}"/>
            </geometry>
            <material name="black">
                <color rgba="0 0 0 1"/>
            </material>
        </visual>
        <collision>
            <origin xyz="0 0 0" rpy="0 0 0" />
            <geometry>
                <cylinder radius="${wheel_radius}" length="${wheel_length}"/>
            </geometry>
        </collision>
        <inertial>
            <mass value="${wheel_mass}"/>
            <origin xyz="0 0 0" rpy="0 0 0"/>
            <inertia ixx="${wheel_mass*(3*wheel_radius*wheel_radius+wheel_length*wheel_length)/12}" ixy = "0" ixz = "0"
                iyy="${wheel_mass*(3*wheel_radius*wheel_radius+wheel_length*wheel_length)/12}" iyz = "0"
                izz="${wheel_mass*wheel_radius*wheel_radius/2}" />
        </inertial>
    </link>
    <gazebo reference="left_front_link">
        <material>Gazebo/Black</material>
    </gazebo>
    <!-- 右前轮 -->
    <joint name="right_front_joint" type="continuous">
        <origin xyz="0.595 -0.265 0.10" rpy="1.57 0 0"/>
        <parent link="base_link"/>
        <child link="right_front_link"/>
        <axis xyz="0 1 0"/>
    </joint>

    <link name="right_front_link">
        <visual>
            <origin xyz="0 0 0" rpy="0 0 0" />
            <geometry>
                <cylinder radius="${wheel_radius}" length="${wheel_length}"/>
            </geometry>
            <material name="black">
                <color rgba="0 0 0 1"/>
            </material>
        </visual>
        <collision>
            <origin xyz="0 0 0" rpy="0 0 0" />
            <geometry>
                <cylinder radius="${wheel_radius}" length="${wheel_length}"/>
            </geometry>
        </collision>
        <inertial>
            <mass value="${wheel_mass}"/>
            <origin xyz="0 0 0" rpy="0 0 0"/>
            <inertia ixx="${wheel_mass*(3*wheel_radius*wheel_radius+wheel_length*wheel_length)/12}" ixy = "0" ixz = "0"
                iyy="${wheel_mass*(3*wheel_radius*wheel_radius+wheel_length*wheel_length)/12}" iyz = "0"
                izz="${wheel_mass*wheel_radius*wheel_radius/2}" />
        </inertial>
    </link>
    <gazebo reference="right_front_link">
        <material>Gazebo/Black</material>
    </gazebo>
</robot>
